Workbook

Sheet Home
B1: Property Operations Toolkit
B2: One command center for work orders, turnover, retention, and service recovery.
B4: PULSE — RIGHT NOW
B5: SLA BREACHES | D5: AT RISK | F5: FOLLOW-UPS DUE | H5: UNITS NOT READY
B6: =COUNTIFS('Work Orders'!L2:L500,"Breached") | D6: =COUNTIFS('Work Orders'!L2:L500,"At Risk") | F6: =COUNTIFS('Service Recovery'!H2:H500,"No",'Service Recovery'!I2:I500,"<>"&"",'Service Recovery'!I2:I500,"<="&TODAY()+2) | H6: =COUNTA(Turnover!A2:A500)-COUNTIFS(Turnover!H2:H500,"Ready")-COUNTIFS(Turnover!H2:H500,"Ready for QC")
B7: View in Action Center → | D7: View in Action Center → | F7: View in Action Center → | H7: View in Action Center →
B9: OPEN A TRACKER
B10: Dashboard | D10: Work Orders | F10: Turnover
B14: Retention | D14: Service Recovery | F14: ⚡ Action Center | H14: Weekly Report
B18: SAMPLE DATA — every number on this page is live. Add a row to any tracker and the pulse, charts, Action Center, and Weekly Report update on their own. Built by Jordan S. Williams · Resident Experience Specialist (Shift Lead)

Sheet Action Center
B1: ⚡ Action Center
B2: Everything that needs you, surfaced automatically. Fix it in the source tracker — this page updates itself.
B3: 🔴 SLA BREACHES — past target, act now
B4: WO-ID | C4: Unit | D4: Priority | E4: Days overdue
A5: =IFERROR(MATCH(1,'Work Orders'!$M$2:$M$500,0)+1,"") | B5: =IF($A5="","",INDEX('Work Orders'!A:A,$A5)) | C5: =IF($A5="","",INDEX('Work Orders'!C:C,$A5)) | D5: =IF($A5="","",INDEX('Work Orders'!E:E,$A5)) | E5: =IF($A5="","",INDEX('Work Orders'!K:K,$A5)-INDEX('Work Orders'!J:J,$A5)) | F5: =IF($A5="","",HYPERLINK("#'Work Orders'!A"&$A5,"Open →"))
A6: =IFERROR(MATCH(2,'Work Orders'!$M$2:$M$500,0)+1,"") | B6: =IF($A6="","",INDEX('Work Orders'!A:A,$A6)) | C6: =IF($A6="","",INDEX('Work Orders'!C:C,$A6)) | D6: =IF($A6="","",INDEX('Work Orders'!E:E,$A6)) | E6: =IF($A6="","",INDEX('Work Orders'!K:K,$A6)-INDEX('Work Orders'!J:J,$A6)) | F6: =IF($A6="","",HYPERLINK("#'Work Orders'!A"&$A6,"Open →"))
A7: =IFERROR(MATCH(3,'Work Orders'!$M$2:$M$500,0)+1,"") | B7: =IF($A7="","",INDEX('Work Orders'!A:A,$A7)) | C7: =IF($A7="","",INDEX('Work Orders'!C:C,$A7)) | D7: =IF($A7="","",INDEX('Work Orders'!E:E,$A7)) | E7: =IF($A7="","",INDEX('Work Orders'!K:K,$A7)-INDEX('Work Orders'!J:J,$A7)) | F7: =IF($A7="","",HYPERLINK("#'Work Orders'!A"&$A7,"Open →"))
A8: =IFERROR(MATCH(4,'Work Orders'!$M$2:$M$500,0)+1,"") | B8: =IF($A8="","",INDEX('Work Orders'!A:A,$A8)) | C8: =IF($A8="","",INDEX('Work Orders'!C:C,$A8)) | D8: =IF($A8="","",INDEX('Work Orders'!E:E,$A8)) | E8: =IF($A8="","",INDEX('Work Orders'!K:K,$A8)-INDEX('Work Orders'!J:J,$A8)) | F8: =IF($A8="","",HYPERLINK("#'Work Orders'!A"&$A8,"Open →"))
A9: =IFERROR(MATCH(5,'Work Orders'!$M$2:$M$500,0)+1,"") | B9: =IF($A9="","",INDEX('Work Orders'!A:A,$A9)) | C9: =IF($A9="","",INDEX('Work Orders'!C:C,$A9)) | D9: =IF($A9="","",INDEX('Work Orders'!E:E,$A9)) | E9: =IF($A9="","",INDEX('Work Orders'!K:K,$A9)-INDEX('Work Orders'!J:J,$A9)) | F9: =IF($A9="","",HYPERLINK("#'Work Orders'!A"&$A9,"Open →"))
A10: =IFERROR(MATCH(6,'Work Orders'!$M$2:$M$500,0)+1,"") | B10: =IF($A10="","",INDEX('Work Orders'!A:A,$A10)) | C10: =IF($A10="","",INDEX('Work Orders'!C:C,$A10)) | D10: =IF($A10="","",INDEX('Work Orders'!E:E,$A10)) | E10: =IF($A10="","",INDEX('Work Orders'!K:K,$A10)-INDEX('Work Orders'!J:J,$A10)) | F10: =IF($A10="","",HYPERLINK("#'Work Orders'!A"&$A10,"Open →"))
A11: =IFERROR(MATCH(7,'Work Orders'!$M$2:$M$500,0)+1,"") | B11: =IF($A11="","",INDEX('Work Orders'!A:A,$A11)) | C11: =IF($A11="","",INDEX('Work Orders'!C:C,$A11)) | D11: =IF($A11="","",INDEX('Work Orders'!E:E,$A11)) | E11: =IF($A11="","",INDEX('Work Orders'!K:K,$A11)-INDEX('Work Orders'!J:J,$A11)) | F11: =IF($A11="","",HYPERLINK("#'Work Orders'!A"&$A11,"Open →"))
A12: =IFERROR(MATCH(8,'Work Orders'!$M$2:$M$500,0)+1,"") | B12: =IF($A12="","",INDEX('Work Orders'!A:A,$A12)) | C12: =IF($A12="","",INDEX('Work Orders'!C:C,$A12)) | D12: =IF($A12="","",INDEX('Work Orders'!E:E,$A12)) | E12: =IF($A12="","",INDEX('Work Orders'!K:K,$A12)-INDEX('Work Orders'!J:J,$A12)) | F12: =IF($A12="","",HYPERLINK("#'Work Orders'!A"&$A12,"Open →"))
B14: 🟡 AT RISK — due within 2 days
B15: WO-ID | C15: Unit | D15: Priority | E15: Days left
A16: =IFERROR(MATCH(1,'Work Orders'!$N$2:$N$500,0)+1,"") | B16: =IF($A16="","",INDEX('Work Orders'!A:A,$A16)) | C16: =IF($A16="","",INDEX('Work Orders'!C:C,$A16)) | D16: =IF($A16="","",INDEX('Work Orders'!E:E,$A16)) | E16: =IF($A16="","",INDEX('Work Orders'!J:J,$A16)-INDEX('Work Orders'!K:K,$A16)) | F16: =IF($A16="","",HYPERLINK("#'Work Orders'!A"&$A16,"Open →"))
A17: =IFERROR(MATCH(2,'Work Orders'!$N$2:$N$500,0)+1,"") | B17: =IF($A17="","",INDEX('Work Orders'!A:A,$A17)) | C17: =IF($A17="","",INDEX('Work Orders'!C:C,$A17)) | D17: =IF($A17="","",INDEX('Work Orders'!E:E,$A17)) | E17: =IF($A17="","",INDEX('Work Orders'!J:J,$A17)-INDEX('Work Orders'!K:K,$A17)) | F17: =IF($A17="","",HYPERLINK("#'Work Orders'!A"&$A17,"Open →"))
A18: =IFERROR(MATCH(3,'Work Orders'!$N$2:$N$500,0)+1,"") | B18: =IF($A18="","",INDEX('Work Orders'!A:A,$A18)) | C18: =IF($A18="","",INDEX('Work Orders'!C:C,$A18)) | D18: =IF($A18="","",INDEX('Work Orders'!E:E,$A18)) | E18: =IF($A18="","",INDEX('Work Orders'!J:J,$A18)-INDEX('Work Orders'!K:K,$A18)) | F18: =IF($A18="","",HYPERLINK("#'Work Orders'!A"&$A18,"Open →"))
A19: =IFERROR(MATCH(4,'Work Orders'!$N$2:$N$500,0)+1,"") | B19: =IF($A19="","",INDEX('Work Orders'!A:A,$A19)) | C19: =IF($A19="","",INDEX('Work Orders'!C:C,$A19)) | D19: =IF($A19="","",INDEX('Work Orders'!E:E,$A19)) | E19: =IF($A19="","",INDEX('Work Orders'!J:J,$A19)-INDEX('Work Orders'!K:K,$A19)) | F19: =IF($A19="","",HYPERLINK("#'Work Orders'!A"&$A19,"Open →"))
A20: =IFERROR(MATCH(5,'Work Orders'!$N$2:$N$500,0)+1,"") | B20: =IF($A20="","",INDEX('Work Orders'!A:A,$A20)) | C20: =IF($A20="","",INDEX('Work Orders'!C:C,$A20)) | D20: =IF($A20="","",INDEX('Work Orders'!E:E,$A20)) | E20: =IF($A20="","",INDEX('Work Orders'!J:J,$A20)-INDEX('Work Orders'!K:K,$A20)) | F20: =IF($A20="","",HYPERLINK("#'Work Orders'!A"&$A20,"Open →"))
A21: =IFERROR(MATCH(6,'Work Orders'!$N$2:$N$500,0)+1,"") | B21: =IF($A21="","",INDEX('Work Orders'!A:A,$A21)) | C21: =IF($A21="","",INDEX('Work Orders'!C:C,$A21)) | D21: =IF($A21="","",INDEX('Work Orders'!E:E,$A21)) | E21: =IF($A21="","",INDEX('Work Orders'!J:J,$A21)-INDEX('Work Orders'!K:K,$A21)) | F21: =IF($A21="","",HYPERLINK("#'Work Orders'!A"&$A21,"Open →"))
B23: 📦 FOLLOW-UPS DUE — within 2 days, still open
B24: Follow-up | C24: Unit | D24: Category | E24: Severity
A25: =IFERROR(MATCH(1,'Service Recovery'!$K$2:$K$500,0)+1,"") | B25: =IF($A25="","",INDEX('Service Recovery'!I:I,$A25)) | C25: =IF($A25="","",INDEX('Service Recovery'!B:B,$A25)) | D25: =IF($A25="","",INDEX('Service Recovery'!C:C,$A25)) | E25: =IF($A25="","",INDEX('Service Recovery'!E:E,$A25)) | F25: =IF($A25="","",HYPERLINK("#'Service Recovery'!A"&$A25,"Open →"))
A26: =IFERROR(MATCH(2,'Service Recovery'!$K$2:$K$500,0)+1,"") | B26: =IF($A26="","",INDEX('Service Recovery'!I:I,$A26)) | C26: =IF($A26="","",INDEX('Service Recovery'!B:B,$A26)) | D26: =IF($A26="","",INDEX('Service Recovery'!C:C,$A26)) | E26: =IF($A26="","",INDEX('Service Recovery'!E:E,$A26)) | F26: =IF($A26="","",HYPERLINK("#'Service Recovery'!A"&$A26,"Open →"))
A27: =IFERROR(MATCH(3,'Service Recovery'!$K$2:$K$500,0)+1,"") | B27: =IF($A27="","",INDEX('Service Recovery'!I:I,$A27)) | C27: =IF($A27="","",INDEX('Service Recovery'!B:B,$A27)) | D27: =IF($A27="","",INDEX('Service Recovery'!C:C,$A27)) | E27: =IF($A27="","",INDEX('Service Recovery'!E:E,$A27)) | F27: =IF($A27="","",HYPERLINK("#'Service Recovery'!A"&$A27,"Open →"))
A28: =IFERROR(MATCH(4,'Service Recovery'!$K$2:$K$500,0)+1,"") | B28: =IF($A28="","",INDEX('Service Recovery'!I:I,$A28)) | C28: =IF($A28="","",INDEX('Service Recovery'!B:B,$A28)) | D28: =IF($A28="","",INDEX('Service Recovery'!C:C,$A28)) | E28: =IF($A28="","",INDEX('Service Recovery'!E:E,$A28)) | F28: =IF($A28="","",HYPERLINK("#'Service Recovery'!A"&$A28,"Open →"))
A29: =IFERROR(MATCH(5,'Service Recovery'!$K$2:$K$500,0)+1,"") | B29: =IF($A29="","",INDEX('Service Recovery'!I:I,$A29)) | C29: =IF($A29="","",INDEX('Service Recovery'!B:B,$A29)) | D29: =IF($A29="","",INDEX('Service Recovery'!C:C,$A29)) | E29: =IF($A29="","",INDEX('Service Recovery'!E:E,$A29)) | F29: =IF($A29="","",HYPERLINK("#'Service Recovery'!A"&$A29,"Open →"))
A30: =IFERROR(MATCH(6,'Service Recovery'!$K$2:$K$500,0)+1,"") | B30: =IF($A30="","",INDEX('Service Recovery'!I:I,$A30)) | C30: =IF($A30="","",INDEX('Service Recovery'!B:B,$A30)) | D30: =IF($A30="","",INDEX('Service Recovery'!C:C,$A30)) | E30: =IF($A30="","",INDEX('Service Recovery'!E:E,$A30)) | F30: =IF($A30="","",HYPERLINK("#'Service Recovery'!A"&$A30,"Open →"))
B32: 🏠 TURNOVER — QC failed, needs rework
B33: Unit | C33: Building | D33: Top deficiency | E33: Deficiencies
A34: =IFERROR(MATCH(1,Turnover!$K$2:$K$500,0)+1,"") | B34: =IF($A34="","",INDEX('Turnover'!A:A,$A34)) | C34: =IF($A34="","",INDEX('Turnover'!B:B,$A34)) | D34: =IF($A34="","",INDEX('Turnover'!G:G,$A34)) | E34: =IF($A34="","",INDEX('Turnover'!F:F,$A34)) | F34: =IF($A34="","",HYPERLINK("#'Turnover'!A"&$A34,"Open →"))
A35: =IFERROR(MATCH(2,Turnover!$K$2:$K$500,0)+1,"") | B35: =IF($A35="","",INDEX('Turnover'!A:A,$A35)) | C35: =IF($A35="","",INDEX('Turnover'!B:B,$A35)) | D35: =IF($A35="","",INDEX('Turnover'!G:G,$A35)) | E35: =IF($A35="","",INDEX('Turnover'!F:F,$A35)) | F35: =IF($A35="","",HYPERLINK("#'Turnover'!A"&$A35,"Open →"))
A36: =IFERROR(MATCH(3,Turnover!$K$2:$K$500,0)+1,"") | B36: =IF($A36="","",INDEX('Turnover'!A:A,$A36)) | C36: =IF($A36="","",INDEX('Turnover'!B:B,$A36)) | D36: =IF($A36="","",INDEX('Turnover'!G:G,$A36)) | E36: =IF($A36="","",INDEX('Turnover'!F:F,$A36)) | F36: =IF($A36="","",HYPERLINK("#'Turnover'!A"&$A36,"Open →"))
A37: =IFERROR(MATCH(4,Turnover!$K$2:$K$500,0)+1,"") | B37: =IF($A37="","",INDEX('Turnover'!A:A,$A37)) | C37: =IF($A37="","",INDEX('Turnover'!B:B,$A37)) | D37: =IF($A37="","",INDEX('Turnover'!G:G,$A37)) | E37: =IF($A37="","",INDEX('Turnover'!F:F,$A37)) | F37: =IF($A37="","",HYPERLINK("#'Turnover'!A"&$A37,"Open →"))
A38: =IFERROR(MATCH(5,Turnover!$K$2:$K$500,0)+1,"") | B38: =IF($A38="","",INDEX('Turnover'!A:A,$A38)) | C38: =IF($A38="","",INDEX('Turnover'!B:B,$A38)) | D38: =IF($A38="","",INDEX('Turnover'!G:G,$A38)) | E38: =IF($A38="","",INDEX('Turnover'!F:F,$A38)) | F38: =IF($A38="","",HYPERLINK("#'Turnover'!A"&$A38,"Open →"))
B40: 🔑 RENEWAL OUTREACH — intent unknown or undecided
B41: Unit | C41: Lease end | D41: Intent | E41: Touches
A42: =IFERROR(MATCH(1,Retention!$J$2:$J$500,0)+1,"") | B42: =IF($A42="","",INDEX('Retention'!A:A,$A42)) | C42: =IF($A42="","",INDEX('Retention'!C:C,$A42)) | D42: =IF($A42="","",INDEX('Retention'!G:G,$A42)) | E42: =IF($A42="","",INDEX('Retention'!F:F,$A42)) | F42: =IF($A42="","",HYPERLINK("#'Retention'!A"&$A42,"Open →"))
A43: =IFERROR(MATCH(2,Retention!$J$2:$J$500,0)+1,"") | B43: =IF($A43="","",INDEX('Retention'!A:A,$A43)) | C43: =IF($A43="","",INDEX('Retention'!C:C,$A43)) | D43: =IF($A43="","",INDEX('Retention'!G:G,$A43)) | E43: =IF($A43="","",INDEX('Retention'!F:F,$A43)) | F43: =IF($A43="","",HYPERLINK("#'Retention'!A"&$A43,"Open →"))
A44: =IFERROR(MATCH(3,Retention!$J$2:$J$500,0)+1,"") | B44: =IF($A44="","",INDEX('Retention'!A:A,$A44)) | C44: =IF($A44="","",INDEX('Retention'!C:C,$A44)) | D44: =IF($A44="","",INDEX('Retention'!G:G,$A44)) | E44: =IF($A44="","",INDEX('Retention'!F:F,$A44)) | F44: =IF($A44="","",HYPERLINK("#'Retention'!A"&$A44,"Open →"))
...

Sheet README
A1: Property Operations Toolkit
A2: Proof of concept · Jordan S. Williams · Resident Experience Specialist (Shift Lead)
A4: All data on this sheet is fictional sample data for demonstration purposes. Replace with live property data to use operationally.
A6: Dashboard | B6: Live KPI summary. Every metric is a formula reading the tracker sheets — no manual tallying.
A7: Work Orders | B7: Full work-order lifecycle: intake → assignment → SLA tracking → close. SLA targets set automatically by priority (Emergency 1d, High 3d, Standard 7d, Low 14d); status flags Breached / At Risk / On Track in real time.
A8: Turnover | B8: Unit make-ready pipeline for move-in surges: inspection → deficiencies → QC → ready. Built for high-volume turnover like a 2,224-unit surge.
A9: Retention | B9: Lease-renewal pipeline: offer sent, outreach touches, resident intent, and at-risk reasons. Retention rate calculated on decided units only.
A10: Service Recovery | B10: Resident experience log: issue → owner → action → follow-up → satisfaction score. Closes the loop on service failures.
A11: Home | B11: App-style launcher: live pulse stats and one-click navigation buttons to every tracker.
A12: Action Center | B12: Your daily priority queue — SLA breaches, at-risk items, due follow-ups, QC failures, and renewal outreach surface automatically via hidden _seq_ helpers. Fix the source row; this page updates itself.
A13: Weekly Report | B13: Print-ready one-pager for standup or 1:1s: this week's numbers plus the top 3 breaches. Every value is a live formula.
A16: How to use it:
A17: 1. | B17: Replace the sample rows with live data (keep the header row and formulas).
A18: 2. | B18: Use the dropdowns — they enforce clean categories for reporting.
A19: 3. | B19: Watch the Dashboard: it updates itself as trackers change.
A20: 4. | B20: Extend it: add sheets per building, pivot the trackers monthly, or feed the data into a BI tool.

Sheet Dashboard
A1: Operations Dashboard
A2: Live KPIs — every value below is a formula. Sample data. | D2: Charts update live from the trackers — see the Action Center for what needs you today →
A4: WORK ORDERS
A5: Open work orders | B5: =COUNTIFS('Work Orders'!H2:H500,"Open")+COUNTIFS('Work Orders'!H2:H500,"In Progress")+COUNTIFS('Work Orders'!H2:H500,"Waiting on Parts")
A6: SLA breaches (open) | B6: =COUNTIFS('Work Orders'!L2:L500,"Breached")
A7: At risk of breach | B7: =COUNTIFS('Work Orders'!L2:L500,"At Risk")
A8: Emergency orders open | B8: =COUNTIFS('Work Orders'!E2:E500,"Emergency",'Work Orders'!H2:H500,"<>Closed")
A9: Avg days to close | B9: =IFERROR(ROUND(AVERAGEIFS('Work Orders'!K2:K500,'Work Orders'!H2:H500,"Closed"),1),"—")
A10: TURNOVER
A11: Units tracked | B11: =COUNTA(Turnover!A2:A500)
A12: Units ready / QC-ready | B12: =COUNTIFS(Turnover!H2:H500,"Ready")+COUNTIFS(Turnover!H2:H500,"Ready for QC")
A13: % ready | B13: =IFERROR((COUNTIFS(Turnover!H2:H500,"Ready")+COUNTIFS(Turnover!H2:H500,"Ready for QC"))/COUNTA(Turnover!A2:A500),0)
A14: Avg days move-out → ready | B14: =IFERROR(ROUND(AVERAGE(Turnover!K2:K500),1),"—")
A15: RETENTION
A16: Leases tracked | B16: =COUNTA(Retention!A2:A500)
A17: Renewing | B17: =COUNTIFS(Retention!G2:G500,"Renewing")
A18: At-risk (undecided + leaving) | B18: =COUNTIFS(Retention!G2:G500,"Undecided")+COUNTIFS(Retention!G2:G500,"Not Renewing")
A19: Retention rate (decided) | B19: =IFERROR(COUNTIFS(Retention!G2:G500,"Renewing")/COUNTIFS(Retention!G2:G500,"<>Unknown",Retention!G2:G500,"<>"),0)
A20: SERVICE RECOVERY
A21: Open recovery items | B21: =COUNTIFS('Service Recovery'!H2:H500,"No")
A22: Avg satisfaction (resolved) | B22: =IFERROR(ROUND(AVERAGE('Service Recovery'!J2:J500),2),"—")
A24: Last updated: | B24: =TODAY()

Sheet Work Orders
A1: WO-ID | B1: Date Opened | C1: Unit | D1: Category | E1: Priority | F1: Description | G1: Assigned To | H1: Status | I1: Date Closed | J1: SLA Target (days) | K1: Days Open | L1: SLA Status | M1: _seq_breach | N1: _seq_risk
A2: WO-1001 | B2: 46293 | C2: A-101 | D2: Plumbing | E2: High | F2: Kitchen sink draining slowly; possible grease buildup | G2: M. Torres | H2: In Progress | J2: =IF(E2="Emergency",1,IF(E2="High",3,IF(E2="Standard",7,14))) | K2: =IF(H2="Closed",I2-B2,TODAY()-B2) | L2: =IF(H2="Closed","Closed",IF(K2>J2,"Breached",IF(K2>=J2-1,"At Risk","On Track"))) | M2: =IF($L2="Breached",COUNTIF($L$2:$L2,"Breached"),"") | N2: =IF($L2="At Risk",COUNTIF($L$2:$L2,"At Risk"),"")
A3: WO-1002 | B3: 46293 | C3: B-214 | D3: HVAC | E3: Emergency | F3: AC not cooling below 78°F; unit running constantly | G3: D. Kim | H3: In Progress | J3: =IF(E3="Emergency",1,IF(E3="High",3,IF(E3="Standard",7,14))) | K3: =IF(H3="Closed",I3-B3,TODAY()-B3) | L3: =IF(H3="Closed","Closed",IF(K3>J3,"Breached",IF(K3>=J3-1,"At Risk","On Track"))) | M3: =IF($L3="Breached",COUNTIF($L$2:$L3,"Breached"),"") | N3: =IF($L3="At Risk",COUNTIF($L$2:$L3,"At Risk"),"")
A4: WO-1003 | B4: 46292 | C4: C-309 | D4: Appliance | E4: Standard | F4: Garbage disposal jammed; humming but not spinning | G4: R. Patel | H4: Open | J4: =IF(E4="Emergency",1,IF(E4="High",3,IF(E4="Standard",7,14))) | K4: =IF(H4="Closed",I4-B4,TODAY()-B4) | L4: =IF(H4="Closed","Closed",IF(K4>J4,"Breached",IF(K4>=J4-1,"At Risk","On Track"))) | M4: =IF($L4="Breached",COUNTIF($L$2:$L4,"Breached"),"") | N4: =IF($L4="At Risk",COUNTIF($L$2:$L4,"At Risk"),"")
A5: WO-1004 | B5: 46292 | C5: A-118 | D5: Lock/Key | E5: High | F5: Bedroom door lock sticking; resident unable to lock | G5: J. Williams | H5: In Progress | J5: =IF(E5="Emergency",1,IF(E5="High",3,IF(E5="Standard",7,14))) | K5: =IF(H5="Closed",I5-B5,TODAY()-B5) | L5: =IF(H5="Closed","Closed",IF(K5>J5,"Breached",IF(K5>=J5-1,"At Risk","On Track"))) | M5: =IF($L5="Breached",COUNTIF($L$2:$L5,"Breached"),"") | N5: =IF($L5="At Risk",COUNTIF($L$2:$L5,"At Risk"),"")
A6: WO-1005 | B6: 46291 | C6: D-102 | D6: Electrical | E6: Standard | F6: Hallway light flickering in entry | G6: M. Torres | H6: Closed | I6: 46292 | J6: =IF(E6="Emergency",1,IF(E6="High",3,IF(E6="Standard",7,14))) | K6: =IF(H6="Closed",I6-B6,TODAY()-B6) | L6: =IF(H6="Closed","Closed",IF(K6>J6,"Breached",IF(K6>=J6-1,"At Risk","On Track"))) | M6: =IF($L6="Breached",COUNTIF($L$2:$L6,"Breached"),"") | N6: =IF($L6="At Risk",COUNTIF($L$2:$L6,"At Risk"),"")
A7: WO-1006 | B7: 46291 | C7: B-207 | D7: Plumbing | E7: Emergency | F7: Water leaking under bathroom sink; shutoff engaged | G7: D. Kim | H7: Closed | I7: 46291 | J7: =IF(E7="Emergency",1,IF(E7="High",3,IF(E7="Standard",7,14))) | K7: =IF(H7="Closed",I7-B7,TODAY()-B7) | L7: =IF(H7="Closed","Closed",IF(K7>J7,"Breached",IF(K7>=J7-1,"At Risk","On Track"))) | M7: =IF($L7="Breached",COUNTIF($L$2:$L7,"Breached"),"") | N7: =IF($L7="At Risk",COUNTIF($L$2:$L7,"At Risk"),"")
A8: WO-1007 | B8: 46290 | C8: C-315 | D8: Appliance | E8: Standard | F8: Dishwasher leaking at front seal during cycle | G8: R. Patel | H8: Waiting on Parts | J8: =IF(E8="Emergency",1,IF(E8="High",3,IF(E8="Standard",7,14))) | K8: =IF(H8="Closed",I8-B8,TODAY()-B8) | L8: =IF(H8="Closed","Closed",IF(K8>J8,"Breached",IF(K8>=J8-1,"At Risk","On Track"))) | M8: =IF($L8="Breached",COUNTIF($L$2:$L8,"Breached"),"") | N8: =IF($L8="At Risk",COUNTIF($L$2:$L8,"At Risk"),"")
A9: WO-1008 | B9: 46290 | C9: A-122 | D9: Electrical | E9: High | F9: Thermostat unresponsive; blank display | G9: M. Torres | H9: Closed | I9: 46291 | J9: =IF(E9="Emergency",1,IF(E9="High",3,IF(E9="Standard",7,14))) | K9: =IF(H9="Closed",I9-B9,TODAY()-B9) | L9: =IF(H9="Closed","Closed",IF(K9>J9,"Breached",IF(K9>=J9-1,"At Risk","On Track"))) | M9: =IF($L9="Breached",COUNTIF($L$2:$L9,"Breached"),"") | N9: =IF($L9="At Risk",COUNTIF($L$2:$L9,"At Risk"),"")
A10: WO-1009 | B10: 46289 | C10: D-118 | D10: Interior | E10: Low | F10: Window screen torn in living room | G10: A. Johnson | H10: Open | J10: =IF(E10="Emergency",1,IF(E10="High",3,IF(E10="Standard",7,14))) | K10: =IF(H10="Closed",I10-B10,TODAY()-B10) | L10: =IF(H10="Closed","Closed",IF(K10>J10,"Breached",IF(K10>=J10-1,"At Risk","On Track"))) | M10: =IF($L10="Breached",COUNTIF($L$2:$L10,"Breached"),"") | N10: =IF($L10="At Risk",COUNTIF($L$2:$L10,"At Risk"),"")
A11: WO-1010 | B11: 46289 | C11: B-201 | D11: Appliance | E11: Standard | F11: Stove burner not igniting; gas smell ruled out | G11: R. Patel | H11: Closed | I11: 46290 | J11: =IF(E11="Emergency",1,IF(E11="High",3,IF(E11="Standard",7,14))) | K11: =IF(H11="Closed",I11-B11,TODAY()-B11) | L11: =IF(H11="Closed","Closed",IF(K11>J11,"Breached",IF(K11>=J11-1,"At Risk","On Track"))) | M11: =IF($L11="Breached",COUNTIF($L$2:$L11,"Breached"),"") | N11: =IF($L11="At Risk",COUNTIF($L$2:$L11,"At Risk"),"")
A12: WO-1011 | B12: 46288 | C12: C-301 | D12: HVAC | E12: High | F12: Weak airflow in bedroom vent; filter replaced, still weak | G12: D. Kim | H12: In Progress | J12: =IF(E12="Emergency",1,IF(E12="High",3,IF(E12="Standard",7,14))) | K12: =IF(H12="Closed",I12-B12,TODAY()-B12) | L12: =IF(H12="Closed","Closed",IF(K12>J12,"Breached",IF(K12>=J12-1,"At Risk","On Track"))) | M12: =IF($L12="Breached",COUNTIF($L$2:$L12,"Breached"),"") | N12: =IF($L12="At Risk",COUNTIF($L$2:$L12,"At Risk"),"")
A13: WO-1012 | B13: 46288 | C13: A-109 | D13: Plumbing | E13: Standard | F13: Toilet running continuously after flush | G13: M. Torres | H13: Closed | I13: 46289 | J13: =IF(E13="Emergency",1,IF(E13="High",3,IF(E13="Standard",7,14))) | K13: =IF(H13="Closed",I13-B13,TODAY()-B13) | L13: =IF(H13="Closed","Closed",IF(K13>J13,"Breached",IF(K13>=J13-1,"At Risk","On Track"))) | M13: =IF($L13="Breached",COUNTIF($L$2:$L13,"Breached"),"") | N13: =IF($L13="At Risk",COUNTIF($L$2:$L13,"At Risk"),"")
A14: WO-1013 | B14: 46287 | C14: D-105 | D14: Pest Control | E14: Standard | F14: Ants along kitchen baseboard near patio door | G14: Vendor: Apex | H14: Closed | I14: 46289 | J14: =IF(E14="Emergency",1,IF(E14="High",3,IF(E14="Standard",7,14))) | K14: =IF(H14="Closed",I14-B14,TODAY()-B14) | L14: =IF(H14="Closed","Closed",IF(K14>J14,"Breached",IF(K14>=J14-1,"At Risk","On Track"))) | M14: =IF($L14="Breached",COUNTIF($L$2:$L14,"Breached"),"") | N14: =IF($L14="At Risk",COUNTIF($L$2:$L14,"At Risk"),"")
A15: WO-1014 | B15: 46287 | C15: B-220 | D15: Electrical | E15: Standard | F15: Bathroom GFCI outlet tripped; will not reset | G15: M. Torres | H15: Open | J15: =IF(E15="Emergency",1,IF(E15="High",3,IF(E15="Standard",7,14))) | K15: =IF(H15="Closed",I15-B15,TODAY()-B15) | L15: =IF(H15="Closed","Closed",IF(K15>J15,"Breached",IF(K15>=J15-1,"At Risk","On Track"))) | M15: =IF($L15="Breached",COUNTIF($L$2:$L15,"Breached"),"") | N15: =IF($L15="At Risk",COUNTIF($L$2:$L15,"At Risk"),"")
A16: WO-1015 | B16: 46286 | C16: C-308 | D16: Interior | E16: Low | F16: Scuffed paint on living room wall near entry | G16: A. Johnson | H16: Closed | I16: 46291 | J16: =IF(E16="Emergency",1,IF(E16="High",3,IF(E16="Standard",7,14))) | K16: =IF(H16="Closed",I16-B16,TODAY()-B16) | L16: =IF(H16="Closed","Closed",IF(K16>J16,"Breached",IF(K16>=J16-1,"At Risk","On Track"))) | M16: =IF($L16="Breached",COUNTIF($L$2:$L16,"Breached"),"") | N16: =IF($L16="At Risk",COUNTIF($L$2:$L16,"At Risk"),"")
A17: WO-1016 | B17: 46286 | C17: A-115 | D17: Appliance | E17: High | F17: Refrigerator not holding temp; food spoilage risk | G17: R. Patel | H17: Closed | I17: 46287 | J17: =IF(E17="Emergency",1,IF(E17="High",3,IF(E17="Standard",7,14))) | K17: =IF(H17="Closed",I17-B17,TODAY()-B17) | L17: =IF(H17="Closed","Closed",IF(K17>J17,"Breached",IF(K17>=J17-1,"At Risk","On Track"))) | M17: =IF($L17="Breached",COUNTIF($L$2:$L17,"Breached"),"") | N17: =IF($L17="At Risk",COUNTIF($L$2:$L17,"At Risk"),"")
A18: WO-1017 | B18: 46285 | C18: D-111 | D18: Plumbing | E18: Standard | F18: Shower head low pressure; likely mineral buildup | G18: M. Torres | H18: Open | J18: =IF(E18="Emergency",1,IF(E18="High",3,IF(E18="Standard",7,14))) | K18: =IF(H18="Closed",I18-B18,TODAY()-B18) | L18: =IF(H18="Closed","Closed",IF(K18>J18,"Breached",IF(K18>=J18-1,"At Risk","On Track"))) | M18: =IF($L18="Breached",COUNTIF($L$2:$L18,"Breached"),"") | N18: =IF($L18="At Risk",COUNTIF($L$2:$L18,"At Risk"),"")
A19: WO-1018 | B19: 46284 | C19: B-212 | D19: Lock/Key | E19: High | F19: Mailbox key broken off in lock | G19: J. Williams | H19: Closed | I19: 46285 | J19: =IF(E19="Emergency",1,IF(E19="High",3,IF(E19="Standard",7,14))) | K19: =IF(H19="Closed",I19-B19,TODAY()-B19) | L19: =IF(H19="Closed","Closed",IF(K19>J19,"Breached",IF(K19>=J19-1,"At Risk","On Track"))) | M19: =IF($L19="Breached",COUNTIF($L$2:$L19,"Breached"),"") | N19: =IF($L19="At Risk",COUNTIF($L$2:$L19,"At Risk"),"")
A20: WO-1019 | B20: 46284 | C20: C-322 | D20: HVAC | E20: Emergency | F20: No cooling at all; compressor not engaging | G20: D. Kim | H20: Closed | I20: 46284 | J20: =IF(E20="Emergency",1,IF(E20="High",3,IF(E20="Standard",7,14))) | K20: =IF(H20="Closed",I20-B20,TODAY()-B20) | L20: =IF(H20="Closed","Closed",IF(K20>J20,"Breached",IF(K20>=J20-1,"At Risk","On Track"))) | M20: =IF($L20="Breached",COUNTIF($L$2:$L20,"Breached"),"") | N20: =IF($L20="At Risk",COUNTIF($L$2:$L20,"At Risk"),"")
A21: WO-1020 | B21: 46283 | C21: A-104 | D21: Exterior/Common Area | E21: Standard | F21: Breezeway light out on 1st floor | G21: M. Torres | H21: Closed | I21: 46284 | J21: =IF(E21="Emergency",1,IF(E21="High",3,IF(E21="Standard",7,14))) | K21: =IF(H21="Closed",I21-B21,TODAY()-B21) | L21: =IF(H21="Closed","Closed",IF(K21>J21,"Breached",IF(K21>=J21-1,"At Risk","On Track"))) | M21: =IF($L21="Breached",COUNTIF($L$2:$L21,"Breached"),"") | N21: =IF($L21="At Risk",COUNTIF($L$2:$L21,"At Risk"),"")
A22: WO-1021 | B22: 46283 | C22: D-120 | D22: Appliance | E22: Low | F22: Microwave turntable not rotating | G22: Unassigned | H22: Open | J22: =IF(E22="Emergency",1,IF(E22="High",3,IF(E22="Standard",7,14))) | K22: =IF(H22="Closed",I22-B22,TODAY()-B22) | L22: =IF(H22="Closed","Closed",IF(K22>J22,"Breached",IF(K22>=J22-1,"At Risk","On Track"))) | M22: =IF($L22="Breached",COUNTIF($L$2:$L22,"Breached"),"") | N22: =IF($L22="At Risk",COUNTIF($L$2:$L22,"At Risk"),"")
A23: WO-1022 | B23: 46282 | C23: B-205 | D23: Plumbing | E23: High | F23: Water heater pilot will not stay lit | G23: D. Kim | H23: Waiting on Parts | J23: =IF(E23="Emergency",1,IF(E23="High",3,IF(E23="Standard",7,14))) | K23: =IF(H23="Closed",I23-B23,TODAY()-B23) | L23: =IF(H23="Closed","Closed",IF(K23>J23,"Breached",IF(K23>=J23-1,"At Risk","On Track"))) | M23: =IF($L23="Breached",COUNTIF($L$2:$L23,"Breached"),"") | N23: =IF($L23="At Risk",COUNTIF($L$2:$L23,"At Risk"),"")
A24: WO-1023 | B24: 46282 | C24: C-305 | D24: Interior | E24: Standard | F24: Closet door off track in primary bedroom | G24: A. Johnson | H24: Closed | I24: 46283 | J24: =IF(E24="Emergency",1,IF(E24="High",3,IF(E24="Standard",7,14))) | K24: =IF(H24="Closed",I24-B24,TODAY()-B24) | L24: =IF(H24="Closed","Closed",IF(K24>J24,"Breached",IF(K24>=J24-1,"At Risk","On Track"))) | M24: =IF($L24="Breached",COUNTIF($L$2:$L24,"Breached"),"") | N24: =IF($L24="At Risk",COUNTIF($L$2:$L24,"At Risk"),"")
A25: WO-1024 | B25: 46281 | C25: A-130 | D25: Electrical | E25: Standard | F25: Ceiling fan wobbling at high speed | G25: M. Torres | H25: Closed | I25: 46282 | J25: =IF(E25="Emergency",1,IF(E25="High",3,IF(E25="Standard",7,14))) | K25: =IF(H25="Closed",I25-B25,TODAY()-B25) | L25: =IF(H25="Closed","Closed",IF(K25>J25,"Breached",IF(K25>=J25-1,"At Risk","On Track"))) | M25: =IF($L25="Breached",COUNTIF($L$2:$L25,"Breached"),"") | N25: =IF($L25="At Risk",COUNTIF($L$2:$L25,"At Risk"),"")
A26: WO-1025 | B26: 46280 | C26: D-108 | D26: Pest Control | E26: High | F26: Wasp nest under stairwell eave near entry | G26: Vendor: Apex | H26: Closed | I26: 46281 | J26: =IF(E26="Emergency",1,IF(E26="High",3,IF(E26="Standard",7,14))) | K26: =IF(H26="Closed",I26-B26,TODAY()-B26) | L26: =IF(H26="Closed","Closed",IF(K26>J26,"Breached",IF(K26>=J26-1,"At Risk","On Track"))) | M26: =IF($L26="Breached",COUNTIF($L$2:$L26,"Breached"),"") | N26: =IF($L26="At Risk",COUNTIF($L$2:$L26,"At Risk"),"")
A27: WO-1026 | B27: 46279 | C27: B-218 | D27: HVAC | E27: Standard | F27: Annual filter + coil check (preventive) | G27: D. Kim | H27: Closed | I27: 46279 | J27: =IF(E27="Emergency",1,IF(E27="High",3,IF(E27="Standard",7,14))) | K27: =IF(H27="Closed",I27-B27,TODAY()-B27) | L27: =IF(H27="Closed","Closed",IF(K27>J27,"Breached",IF(K27>=J27-1,"At Risk","On Track"))) | M27: =IF($L27="Breached",COUNTIF($L$2:$L27,"Breached"),"") | N27: =IF($L27="At Risk",COUNTIF($L$2:$L27,"At Risk"),"")
A28: WO-1027 | B28: 46277 | C28: C-318 | D28: Plumbing | E28: Low | F28: Slow drip at tub spout when off | G28: Unassigned | H28: Open | J28: =IF(E28="Emergency",1,IF(E28="High",3,IF(E28="Standard",7,14))) | K28: =IF(H28="Closed",I28-B28,TODAY()-B28) | L28: =IF(H28="Closed","Closed",IF(K28>J28,"Breached",IF(K28>=J28-1,"At Risk","On Track"))) | M28: =IF($L28="Breached",COUNTIF($L$2:$L28,"Breached"),"") | N28: =IF($L28="At Risk",COUNTIF($L$2:$L28,"At Risk"),"")
A29: WO-1028 | B29: 46275 | C29: A-112 | D29: Interior | E29: Low | F29: Touch-up paint: hallway scuffs | G29: A. Johnson | H29: Open | J29: =IF(E29="Emergency",1,IF(E29="High",3,IF(E29="Standard",7,14))) | K29: =IF(H29="Closed",I29-B29,TODAY()-B29) | L29: =IF(H29="Closed","Closed",IF(K29>J29,"Breached",IF(K29>=J29-1,"At Risk","On Track"))) | M29: =IF($L29="Breached",COUNTIF($L$2:$L29,"Breached"),"") | N29: =IF($L29="At Risk",COUNTIF($L$2:$L29,"At Risk"),"")
M30: =IF($L30="Breached",COUNTIF($L$2:$L30,"Breached"),"") | N30: =IF($L30="At Risk",COUNTIF($L$2:$L30,"At Risk"),"")
M31: =IF($L31="Breached",COUNTIF($L$2:$L31,"Breached"),"") | N31: =IF($L31="At Risk",COUNTIF($L$2:$L31,"At Risk"),"")
M32: =IF($L32="Breached",COUNTIF($L$2:$L32,"Breached"),"") | N32: =IF($L32="At Risk",COUNTIF($L$2:$L32,"At Risk"),"")
M33: =IF($L33="Breached",COUNTIF($L$2:$L33,"Breached"),"") | N33: =IF($L33="At Risk",COUNTIF($L$2:$L33,"At Risk"),"")
M34: =IF($L34="Breached",COUNTIF($L$2:$L34,"Breached"),"") | N34: =IF($L34="At Risk",COUNTIF($L$2:$L34,"At Risk"),"")
M35: =IF($L35="Breached",COUNTIF($L$2:$L35,"Breached"),"") | N35: =IF($L35="At Risk",COUNTIF($L$2:$L35,"At Risk"),"")
M36: =IF($L36="Breached",COUNTIF($L$2:$L36,"Breached"),"") | N36: =IF($L36="At Risk",COUNTIF($L$2:$L36,"At Risk"),"")
M37: =IF($L37="Breached",COUNTIF($L$2:$L37,"Breached"),"") | N37: =IF($L37="At Risk",COUNTIF($L$2:$L37,"At Risk"),"")
M38: =IF($L38="Breached",COUNTIF($L$2:$L38,"Breached"),"") | N38: =IF($L38="At Risk",COUNTIF($L$2:$L38,"At Risk"),"")
M39: =IF($L39="Breached",COUNTIF($L$2:$L39,"Breached"),"") | N39: =IF($L39="At Risk",COUNTIF($L$2:$L39,"At Risk"),"")
M40: =IF($L40="Breached",COUNTIF($L$2:$L40,"Breached"),"") | N40: =IF($L40="At Risk",COUNTIF($L$2:$L40,"At Risk"),"")
...

Sheet Turnover
A1: Unit | B1: Building | C1: Move-Out Date | D1: Inspection Date | E1: Inspector | F1: Deficiencies Found | G1: Top Deficiency | H1: Make-Ready Status | I1: QC Pass | J1: Ready Date | K1: _seq_qcfail
A2: A-101 | B2: A | C2: 46231 | D2: 46232 | E2: J. Williams | F2: 4 | G2: Paint | H2: Ready | I2: Yes | J2: 46238 | K2: =IF($I2="No",COUNTIF($I$2:$I2,"No"),"")
A3: A-115 | B3: A | C3: 46231 | D3: 46232 | E3: J. Williams | F3: 7 | G3: Flooring | H3: Ready | I3: Yes | J3: 46241 | K3: =IF($I3="No",COUNTIF($I$2:$I3,"No"),"")
A4: A-122 | B4: A | C4: 46232 | D4: 46233 | E4: M. Torres | F4: 2 | G4: Cleaning | H4: Ready | I4: Yes | J4: 46237 | K4: =IF($I4="No",COUNTIF($I$2:$I4,"No"),"")
A5: B-201 | B5: B | C5: 46232 | D5: 46233 | E5: M. Torres | F5: 5 | G5: Appliance | H5: Ready | I5: Yes | J5: 46240 | K5: =IF($I5="No",COUNTIF($I$2:$I5,"No"),"")
A6: B-207 | B6: B | C6: 46233 | D6: 46234 | E6: D. Kim | F6: 9 | G6: Plumbing | H6: Ready for QC | I6: Pending | K6: =IF($I6="No",COUNTIF($I$2:$I6,"No"),"")
A7: B-214 | B7: B | C7: 46233 | D7: 46234 | E7: D. Kim | F7: 3 | G7: Paint | H7: Ready | I7: Yes | J7: 46239 | K7: =IF($I7="No",COUNTIF($I$2:$I7,"No"),"")
A8: C-301 | B8: C | C8: 46234 | D8: 46235 | E8: R. Patel | F8: 6 | G8: Damaged Fixture | H8: In Progress | I8: Pending | K8: =IF($I8="No",COUNTIF($I$2:$I8,"No"),"")
A9: C-308 | B9: C | C9: 46234 | D9: 46235 | E9: R. Patel | F9: 1 | G9: Cleaning | H9: Ready | I9: Yes | J9: 46237 | K9: =IF($I9="No",COUNTIF($I$2:$I9,"No"),"")
A10: C-315 | B10: C | C10: 46235 | D10: 46236 | E10: A. Johnson | F10: 8 | G10: Flooring | H10: In Progress | I10: Pending | K10: =IF($I10="No",COUNTIF($I$2:$I10,"No"),"")
A11: D-102 | B11: D | C11: 46235 | D11: 46236 | E11: A. Johnson | F11: 2 | G11: Paint | H11: Ready | I11: Yes | J11: 46239 | K11: =IF($I11="No",COUNTIF($I$2:$I11,"No"),"")
A12: D-108 | B12: D | C12: 46236 | D12: 46237 | E12: J. Williams | F12: 4 | G12: Appliance | H12: Ready for QC | I12: Pending | K12: =IF($I12="No",COUNTIF($I$2:$I12,"No"),"")
A13: D-111 | B13: D | C13: 46236 | D13: 46237 | E13: J. Williams | F13: 0 | G13: None | H13: Ready | I13: Yes | J13: 46238 | K13: =IF($I13="No",COUNTIF($I$2:$I13,"No"),"")
A14: A-104 | B14: A | C14: 46237 | D14: 46238 | E14: M. Torres | F14: 5 | G14: Plumbing | H14: In Progress | I14: Pending | K14: =IF($I14="No",COUNTIF($I$2:$I14,"No"),"")
A15: A-109 | B15: A | C15: 46237 | D15: 46238 | E15: M. Torres | F15: 3 | G15: Electrical | H15: Ready for QC | I15: No | K15: =IF($I15="No",COUNTIF($I$2:$I15,"No"),"")
A16: B-205 | B16: B | C16: 46238 | D16: 46239 | E16: D. Kim | F16: 6 | G16: Paint | H16: In Progress | I16: Pending | K16: =IF($I16="No",COUNTIF($I$2:$I16,"No"),"")
A17: B-212 | B17: B | C17: 46238 | D17: 46239 | E17: D. Kim | F17: 2 | G17: Cleaning | H17: Not Started | I17: Pending | K17: =IF($I17="No",COUNTIF($I$2:$I17,"No"),"")
A18: C-305 | B18: C | C18: 46239 | D18: 46240 | E18: R. Patel | F18: 4 | G18: Damaged Fixture | H18: In Progress | I18: Pending | K18: =IF($I18="No",COUNTIF($I$2:$I18,"No"),"")
A19: C-318 | B19: C | C19: 46239 | D19: 46240 | E19: R. Patel | F19: 7 | G19: Flooring | H19: Not Started | I19: Pending | K19: =IF($I19="No",COUNTIF($I$2:$I19,"No"),"")
A20: D-105 | B20: D | C20: 46240 | D20: 46241 | E20: A. Johnson | F20: 1 | G20: Cleaning | H20: Ready | I20: Yes | J20: 46242 | K20: =IF($I20="No",COUNTIF($I$2:$I20,"No"),"")
A21: D-118 | B21: D | C21: 46240 | D21: 46241 | E21: A. Johnson | F21: 3 | G21: Paint | H21: In Progress | I21: Pending | K21: =IF($I21="No",COUNTIF($I$2:$I21,"No"),"")
A22: A-118 | B22: A | C22: 46241 | D22: 46242 | E22: J. Williams | F22: 5 | G22: Appliance | H22: Not Started | I22: Pending | K22: =IF($I22="No",COUNTIF($I$2:$I22,"No"),"")
A23: B-220 | B23: B | C23: 46241 | D23: 46242 | E23: M. Torres | F23: 2 | G23: Electrical | H23: In Progress | I23: Pending | K23: =IF($I23="No",COUNTIF($I$2:$I23,"No"),"")
K24: =IF($I24="No",COUNTIF($I$2:$I24,"No"),"")
K25: =IF($I25="No",COUNTIF($I$2:$I25,"No"),"")
K26: =IF($I26="No",COUNTIF($I$2:$I26,"No"),"")
K27: =IF($I27="No",COUNTIF($I$2:$I27,"No"),"")
K28: =IF($I28="No",COUNTIF($I$2:$I28,"No"),"")
K29: =IF($I29="No",COUNTIF($I$2:$I29,"No"),"")
K30: =IF($I30="No",COUNTIF($I$2:$I30,"No"),"")
K31: =IF($I31="No",COUNTIF($I$2:$I31,"No"),"")
K32: =IF($I32="No",COUNTIF($I$2:$I32,"No"),"")
K33: =IF($I33="No",COUNTIF($I$2:$I33,"No"),"")
K34: =IF($I34="No",COUNTIF($I$2:$I34,"No"),"")
K35: =IF($I35="No",COUNTIF($I$2:$I35,"No"),"")
... K500: =IF($I500="No",COUNTIF($I$2:$I500,"No"),"")

Sheet Retention
A1: Unit | B1: Resident ID | C1: Lease End | D1: Monthly Rent | E1: Renewal Offer Sent | F1: Outreach Touches | G1: Intent | H1: Reason (if leaving) | I1: Notes | J1: _seq_outreach
A2: A-101 | B2: R-001 | C2: 46326 | D2: 1249 | E2: Yes | F2: 3 | G2: Renewing | H2: N/A | I2: Signed 12-mo renewal; roommate staying | J2: =IF(OR($G2="Unknown",$G2="Undecided"),COUNTIFS($G$2:$G2,"Unknown")+COUNTIFS($G$2:$G2,"Undecided"),"")
A3: A-104 | B3: R-002 | C3: 46326 | D3: 1199 | E3: Yes | F3: 2 | G3: Undecided | H3: N/A | I3: Comparing nearby property; follow up 10/7 | J3: =IF(OR($G3="Unknown",$G3="Undecided"),COUNTIFS($G$2:$G3,"Unknown")+COUNTIFS($G$2:$G3,"Undecided"),"")
A4: A-109 | B4: R-003 | C4: 46356 | D4: 1299 | E4: Yes | F4: 4 | G4: Renewing | H4: N/A | I4: Renewed after service recovery on AC issue | J4: =IF(OR($G4="Unknown",$G4="Undecided"),COUNTIFS($G$2:$G4,"Unknown")+COUNTIFS($G$2:$G4,"Undecided"),"")
A5: A-112 | B5: R-004 | C5: 46326 | D5: 1149 | E5: No | F5: 1 | G5: Unknown | H5: N/A | I5: No contact yet; priority outreach | J5: =IF(OR($G5="Unknown",$G5="Undecided"),COUNTIFS($G$2:$G5,"Unknown")+COUNTIFS($G$2:$G5,"Undecided"),"")
A6: A-115 | B6: R-005 | C6: 46356 | D6: 1349 | E6: Yes | F6: 2 | G6: Not Renewing | H6: Relocating | I6: Job transfer out of state | J6: =IF(OR($G6="Unknown",$G6="Undecided"),COUNTIFS($G$2:$G6,"Unknown")+COUNTIFS($G$2:$G6,"Undecided"),"")
A7: A-118 | B7: R-006 | C7: 46387 | D7: 1249 | E7: No | F7: 0 | G7: Unknown | H7: N/A | J7: =IF(OR($G7="Unknown",$G7="Undecided"),COUNTIFS($G$2:$G7,"Unknown")+COUNTIFS($G$2:$G7,"Undecided"),"")
A8: A-122 | B8: R-007 | C8: 46326 | D8: 1199 | E8: Yes | F8: 5 | G8: Renewing | H8: N/A | I8: Long-term resident; requested same unit | J8: =IF(OR($G8="Unknown",$G8="Undecided"),COUNTIFS($G$2:$G8,"Unknown")+COUNTIFS($G$2:$G8,"Undecided"),"")
A9: A-130 | B9: R-008 | C9: 46356 | D9: 1099 | E9: Yes | F9: 3 | G9: Undecided | H9: N/A | I9: Price-sensitive; reviewing concession options | J9: =IF(OR($G9="Unknown",$G9="Undecided"),COUNTIFS($G$2:$G9,"Unknown")+COUNTIFS($G$2:$G9,"Undecided"),"")
A10: B-201 | B10: R-009 | C10: 46326 | D10: 1299 | E10: Yes | F10: 2 | G10: Renewing | H10: N/A | J10: =IF(OR($G10="Unknown",$G10="Undecided"),COUNTIFS($G$2:$G10,"Unknown")+COUNTIFS($G$2:$G10,"Undecided"),"")
A11: B-205 | B11: R-010 | C11: 46356 | D11: 1249 | E11: Yes | F11: 4 | G11: Not Renewing | H11: Roommate Change | I11: Roommate graduating; can't cover solo | J11: =IF(OR($G11="Unknown",$G11="Undecided"),COUNTIFS($G$2:$G11,"Unknown")+COUNTIFS($G$2:$G11,"Undecided"),"")
A12: B-207 | B12: R-011 | C12: 46326 | D12: 1349 | E12: Yes | F12: 3 | G12: Renewing | H12: N/A | J12: =IF(OR($G12="Unknown",$G12="Undecided"),COUNTIFS($G$2:$G12,"Unknown")+COUNTIFS($G$2:$G12,"Undecided"),"")
A13: B-212 | B13: R-012 | C13: 46387 | D13: 1199 | E13: No | F13: 1 | G13: Unknown | H13: N/A | J13: =IF(OR($G13="Unknown",$G13="Undecided"),COUNTIFS($G$2:$G13,"Unknown")+COUNTIFS($G$2:$G13,"Undecided"),"")
A14: B-214 | B14: R-013 | C14: 46326 | D14: 1299 | E14: Yes | F14: 6 | G14: Renewing | H14: N/A | I14: Recovered after repeated HVAC issues; personal follow-ups | J14: =IF(OR($G14="Unknown",$G14="Undecided"),COUNTIFS($G$2:$G14,"Unknown")+COUNTIFS($G$2:$G14,"Undecided"),"")
A15: B-218 | B15: R-014 | C15: 46356 | D15: 1149 | E15: Yes | F15: 2 | G15: Undecided | H15: N/A | I15: Noise concerns; offered unit transfer info | J15: =IF(OR($G15="Unknown",$G15="Undecided"),COUNTIFS($G$2:$G15,"Unknown")+COUNTIFS($G$2:$G15,"Undecided"),"")
A16: B-220 | B16: R-015 | C16: 46326 | D16: 1249 | E16: Yes | F16: 3 | G16: Not Renewing | H16: Price | I16: Found cheaper option nearby | J16: =IF(OR($G16="Unknown",$G16="Undecided"),COUNTIFS($G$2:$G16,"Unknown")+COUNTIFS($G$2:$G16,"Undecided"),"")
A17: C-301 | B17: R-016 | C17: 46356 | D17: 1399 | E17: Yes | F17: 2 | G17: Renewing | H17: N/A | J17: =IF(OR($G17="Unknown",$G17="Undecided"),COUNTIFS($G$2:$G17,"Unknown")+COUNTIFS($G$2:$G17,"Undecided"),"")
A18: C-305 | B18: R-017 | C18: 46326 | D18: 1299 | E18: Yes | F18: 4 | G18: Undecided | H18: N/A | I18: Service experience concerns; manager follow-up scheduled | J18: =IF(OR($G18="Unknown",$G18="Undecided"),COUNTIFS($G$2:$G18,"Unknown")+COUNTIFS($G$2:$G18,"Undecided"),"")
A19: C-308 | B19: R-018 | C19: 46387 | D19: 1249 | E19: No | F19: 0 | G19: Unknown | H19: N/A | J19: =IF(OR($G19="Unknown",$G19="Undecided"),COUNTIFS($G$2:$G19,"Unknown")+COUNTIFS($G$2:$G19,"Undecided"),"")
A20: C-309 | B20: R-019 | C20: 46326 | D20: 1199 | E20: Yes | F20: 3 | G20: Renewing | H20: N/A | J20: =IF(OR($G20="Unknown",$G20="Undecided"),COUNTIFS($G$2:$G20,"Unknown")+COUNTIFS($G$2:$G20,"Undecided"),"")
A21: C-315 | B21: R-020 | C21: 46356 | D21: 1349 | E21: Yes | F21: 2 | G21: Not Renewing | H21: Service Experience | I21: Multiple maintenance delays; exit interview offered | J21: =IF(OR($G21="Unknown",$G21="Undecided"),COUNTIFS($G$2:$G21,"Unknown")+COUNTIFS($G$2:$G21,"Undecided"),"")
A22: C-318 | B22: R-021 | C22: 46326 | D22: 1299 | E22: Yes | F22: 5 | G22: Renewing | H22: N/A | J22: =IF(OR($G22="Unknown",$G22="Undecided"),COUNTIFS($G$2:$G22,"Unknown")+COUNTIFS($G$2:$G22,"Undecided"),"")
A23: C-322 | B23: R-022 | C23: 46356 | D23: 1449 | E23: Yes | F23: 1 | G23: Unknown | H23: N/A | I23: New outreach started | J23: =IF(OR($G23="Unknown",$G23="Undecided"),COUNTIFS($G$2:$G23,"Unknown")+COUNTIFS($G$2:$G23,"Undecided"),"")
A24: D-102 | B24: R-023 | C24: 46326 | D24: 1149 | E24: Yes | F24: 3 | G24: Renewing | H24: N/A | J24: =IF(OR($G24="Unknown",$G24="Undecided"),COUNTIFS($G$2:$G24,"Unknown")+COUNTIFS($G$2:$G24,"Undecided"),"")
A25: D-105 | B25: R-024 | C25: 46387 | D25: 1199 | E25: No | F25: 0 | G25: Unknown | H25: N/A | J25: =IF(OR($G25="Unknown",$G25="Undecided"),COUNTIFS($G$2:$G25,"Unknown")+COUNTIFS($G$2:$G25,"Undecided"),"")
J26: =IF(OR($G26="Unknown",$G26="Undecided"),COUNTIFS($G$2:$G26,"Unknown")+COUNTIFS($G$2:$G26,"Undecided"),"")
J27: =IF(OR($G27="Unknown",$G27="Undecided"),COUNTIFS($G$2:$G27,"Unknown")+COUNTIFS($G$2:$G27,"Undecided"),"")
J28: =IF(OR($G28="Unknown",$G28="Undecided"),COUNTIFS($G$2:$G28,"Unknown")+COUNTIFS($G$2:$G28,"Undecided"),"")
J29: =IF(OR($G29="Unknown",$G29="Undecided"),COUNTIFS($G$2:$G29,"Unknown")+COUNTIFS($G$2:$G29,"Undecided"),"")
J30: =IF(OR($G30="Unknown",$G30="Undecided"),COUNTIFS($G$2:$G30,"Unknown")+COUNTIFS($G$2:$G30,"Undecided"),"")
J31: =IF(OR($G31="Unknown",$G31="Undecided"),COUNTIFS($G$2:$G31,"Unknown")+COUNTIFS($G$2:$G31,"Undecided"),"")
J32: =IF(OR($G32="Unknown",$G32="Undecided"),COUNTIFS($G$2:$G32,"Unknown")+COUNTIFS($G$2:$G32,"Undecided"),"")
J33: =IF(OR($G33="Unknown",$G33="Undecided"),COUNTIFS($G$2:$G33,"Unknown")+COUNTIFS($G$2:$G33,"Undecided"),"")
J34: =IF(OR($G34="Unknown",$G34="Undecided"),COUNTIFS($G$2:$G34,"Unknown")+COUNTIFS($G$2:$G34,"Undecided"),"")
J35: =IF(OR($G35="Unknown",$G35="Undecided"),COUNTIFS($G$2:$G35,"Unknown")+COUNTIFS($G$2:$G35,"Undecided"),"")
J36: =IF(OR($G36="Unknown",$G36="Undecided"),COUNTIFS($G$2:$G36,"Unknown")+COUNTIFS($G$2:$G36,"Undecided"),"")
J37: =IF(OR($G37="Unknown",$G37="Undecided"),COUNTIFS($G$2:$G37,"Unknown")+COUNTIFS($G$2:$G37,"Undecided"),"")
... J500: =IF(OR($G500="Unknown",$G500="Undecided"),COUNTIFS($G$2:$G500,"Unknown")+COUNTIFS($G$2:$G500,"Undecided"),"")

Sheet Service Recovery
A1: Date | B1: Unit | C1: Issue Category | D1: Description | E1: Severity | F1: Owner | G1: Action Taken | H1: Resolved | I1: Follow-Up Date | J1: Satisfaction (1-5) | K1: _seq_followup
A2: 46292 | B2: B-214 | C2: Maintenance Delay | D2: Third HVAC visit for same issue; resident frustrated | E2: High | F2: J. Williams | G2: Escalated to vendor supervisor; loaned portable AC unit | H2: Yes | I2: 46295 | J2: 5 | K2: =IF(AND($H2="No",$I2<>"",$I2<=TODAY()+2),COUNTIFS($H$2:$H2,"No",$I$2:$I2,"<>"&"",$I$2:$I2,"<="&TODAY()+2),"")
A3: 46291 | B3: C-305 | C3: Service Experience | D3: Front desk gave wrong package locker code twice | E3: Medium | F3: J. Williams | G3: Apologized in person; walked resident through Parcel Pending app | H3: Yes | I3: 46294 | J3: 4 | K3: =IF(AND($H3="No",$I3<>"",$I3<=TODAY()+2),COUNTIFS($H$2:$H3,"No",$I$2:$I3,"<>"&"",$I$2:$I3,"<="&TODAY()+2),"")
A4: 46290 | B4: D-118 | C4: Noise Complaint | D4: Ongoing late-night noise from unit above | E4: Medium | F4: M. Torres | G4: Contacted upstairs resident; issued courtesy notice; scheduled follow-up | H4: No | I4: 46297 | K4: =IF(AND($H4="No",$I4<>"",$I4<=TODAY()+2),COUNTIFS($H$2:$H4,"No",$I$2:$I4,"<>"&"",$I$2:$I4,"<="&TODAY()+2),"")
A5: 46289 | B5: A-115 | C5: Move-In Condition | D5: Unit not fully cleaned at move-in; dust on surfaces | E5: High | F5: J. Williams | G5: Dispatched cleaning crew same day; $50 account credit | H5: Yes | I5: 46292 | J5: 5 | K5: =IF(AND($H5="No",$I5<>"",$I5<=TODAY()+2),COUNTIFS($H$2:$H5,"No",$I$2:$I5,"<>"&"",$I$2:$I5,"<="&TODAY()+2),"")
A6: 46288 | B6: C-315 | C6: Maintenance Delay | D6: Flooring repair rescheduled twice without notice | E6: High | F6: R. Patel | G6: Called resident directly; committed date met; supervisor QC walk | H6: Yes | I6: 46293 | J6: 4 | K6: =IF(AND($H6="No",$I6<>"",$I6<=TODAY()+2),COUNTIFS($H$2:$H6,"No",$I$2:$I6,"<>"&"",$I$2:$I6,"<="&TODAY()+2),"")
A7: 46287 | B7: B-201 | C7: Parking Dispute | D7: Assigned spot repeatedly taken by guest vehicle | E7: Low | F7: M. Torres | G7: Posted reminder notice; towing policy explained to both parties | H7: Yes | I7: 46290 | J7: 4 | K7: =IF(AND($H7="No",$I7<>"",$I7<=TODAY()+2),COUNTIFS($H$2:$H7,"No",$I$2:$I7,"<>"&"",$I$2:$I7,"<="&TODAY()+2),"")
A8: 46286 | B8: D-102 | C8: Package Issue | D8: Package marked delivered but not in locker | E8: Medium | F8: J. Williams | G8: Reviewed Parcel Pending logs + CCTV; located in wrong locker; delivered | H8: Yes | I8: 46289 | J8: 5 | K8: =IF(AND($H8="No",$I8<>"",$I8<=TODAY()+2),COUNTIFS($H$2:$H8,"No",$I$2:$I8,"<>"&"",$I$2:$I8,"<="&TODAY()+2),"")
A9: 46285 | B9: A-122 | C9: Access Issue | D9: Fob stopped working overnight; resident locked out at 1 AM | E9: Critical | F9: J. Williams | G9: Immediate re-encode via Salto; escorted resident; incident documented | H9: Yes | I9: 46288 | J9: 5 | K9: =IF(AND($H9="No",$I9<>"",$I9<=TODAY()+2),COUNTIFS($H$2:$H9,"No",$I$2:$I9,"<>"&"",$I$2:$I9,"<="&TODAY()+2),"")
A10: 46284 | B10: C-308 | C10: Common Area | D10: Pool gate latch broken; safety concern raised | E10: High | F10: D. Kim | G10: Temporary lock + signage same night; work order WO-1019 linked | H10: Yes | I10: 46287 | J10: 4 | K10: =IF(AND($H10="No",$I10<>"",$I10<=TODAY()+2),COUNTIFS($H$2:$H10,"No",$I$2:$I10,"<>"&"",$I$2:$I10,"<="&TODAY()+2),"")
A11: 46283 | B11: B-207 | C11: Billing Question | D11: Utility overage charge disputed | E11: Low | F11: M. Torres | G11: Pulled meter history; walked through bill line by line | H11: Yes | I11: 46286 | J11: 3 | K11: =IF(AND($H11="No",$I11<>"",$I11<=TODAY()+2),COUNTIFS($H$2:$H11,"No",$I$2:$I11,"<>"&"",$I$2:$I11,"<="&TODAY()+2),"")
A12: 46282 | B12: D-105 | C12: Pest Control | D12: Ants returned one week after treatment | E12: Medium | F12: Vendor: Apex | G12: Re-treatment scheduled; sealed entry point found during inspection | H12: No | I12: 46296 | K12: =IF(AND($H12="No",$I12<>"",$I12<=TODAY()+2),COUNTIFS($H$2:$H12,"No",$I$2:$I12,"<>"&"",$I$2:$I12,"<="&TODAY()+2),"")
A13: 46281 | B13: A-109 | C13: Maintenance Delay | D13: Toilet repair took 4 days; resident escalated | E13: Medium | F13: J. Williams | G13: Apology + timeline explanation; prioritized completion; credit offered | H13: Yes | I13: 46284 | J13: 4 | K13: =IF(AND($H13="No",$I13<>"",$I13<=TODAY()+2),COUNTIFS($H$2:$H13,"No",$I$2:$I13,"<>"&"",$I$2:$I13,"<="&TODAY()+2),"")
A14: 46280 | B14: C-322 | C14: Move-In Condition | D14: Missing smoke detector in bedroom at move-in | E14: Critical | F14: J. Williams | G14: Installed within 2 hours; full unit safety re-check completed | H14: Yes | I14: 46283 | J14: 5 | K14: =IF(AND($H14="No",$I14<>"",$I14<=TODAY()+2),COUNTIFS($H$2:$H14,"No",$I$2:$I14,"<>"&"",$I$2:$I14,"<="&TODAY()+2),"")
A15: 46279 | B15: B-218 | C15: Noise Complaint | D15: Bass noise during quiet hours; second report | E15: Medium | F15: M. Torres | G15: Second notice issued; documented for lease enforcement file | H15: No | I15: 46298 | K15: =IF(AND($H15="No",$I15<>"",$I15<=TODAY()+2),COUNTIFS($H$2:$H15,"No",$I$2:$I15,"<>"&"",$I$2:$I15,"<="&TODAY()+2),"")
A16: 46277 | B16: D-111 | C16: Amenity Access | D16: Gym fob access denied erroneously | E16: Low | F16: A. Johnson | G16: Re-synced access group in Salto; confirmed working | H16: Yes | I16: 46280 | J16: 5 | K16: =IF(AND($H16="No",$I16<>"",$I16<=TODAY()+2),COUNTIFS($H$2:$H16,"No",$I$2:$I16,"<>"&"",$I$2:$I16,"<="&TODAY()+2),"")
K17: =IF(AND($H17="No",$I17<>"",$I17<=TODAY()+2),COUNTIFS($H$2:$H17,"No",$I$2:$I17,"<>"&"",$I$2:$I17,"<="&TODAY()+2),"")
K18: =IF(AND($H18="No",$I18<>"",$I18<=TODAY()+2),COUNTIFS($H$2:$H18,"No",$I$2:$I18,"<>"&"",$I$2:$I18,"<="&TODAY()+2),"")
K19: =IF(AND($H19="No",$I19<>"",$I19<=TODAY()+2),COUNTIFS($H$2:$H19,"No",$I$2:$I19,"<>"&"",$I$2:$I19,"<="&TODAY()+2),"")
K20: =IF(AND($H20="No",$I20<>"",$I20<=TODAY()+2),COUNTIFS($H$2:$H20,"No",$I$2:$I20,"<>"&"",$I$2:$I20,"<="&TODAY()+2),"")
K21: =IF(AND($H21="No",$I21<>"",$I21<=TODAY()+2),COUNTIFS($H$2:$H21,"No",$I$2:$I21,"<>"&"",$I$2:$I21,"<="&TODAY()+2),"")
K22: =IF(AND($H22="No",$I22<>"",$I22<=TODAY()+2),COUNTIFS($H$2:$H22,"No",$I$2:$I22,"<>"&"",$I$2:$I22,"<="&TODAY()+2),"")
K23: =IF(AND($H23="No",$I23<>"",$I23<=TODAY()+2),COUNTIFS($H$2:$H23,"No",$I$2:$I23,"<>"&"",$I$2:$I23,"<="&TODAY()+2),"")
K24: =IF(AND($H24="No",$I24<>"",$I24<=TODAY()+2),COUNTIFS($H$2:$H24,"No",$I$2:$I24,"<>"&"",$I$2:$I24,"<="&TODAY()+2),"")
K25: =IF(AND($H25="No",$I25<>"",$I25<=TODAY()+2),COUNTIFS($H$2:$H25,"No",$I$2:$I25,"<>"&"",$I$2:$I25,"<="&TODAY()+2),"")
K26: =IF(AND($H26="No",$I26<>"",$I26<=TODAY()+2),COUNTIFS($H$2:$H26,"No",$I$2:$I26,"<>"&"",$I$2:$I26,"<="&TODAY()+2),"")
K27: =IF(AND($H27="No",$I27<>"",$I27<=TODAY()+2),COUNTIFS($H$2:$H27,"No",$I$2:$I27,"<>"&"",$I$2:$I27,"<="&TODAY()+2),"")
K28: =IF(AND($H28="No",$I28<>"",$I28<=TODAY()+2),COUNTIFS($H$2:$H28,"No",$I$2:$I28,"<>"&"",$I$2:$I28,"<="&TODAY()+2),"")
... K500: =IF(AND($H500="No",$I500<>"",$I500<=TODAY()+2),COUNTIFS($H$2:$H500,"No",$I$2:$I500,"<>"&"",$I$2:$I500,"<="&TODAY()+2),"")

Sheet ChartData
A1: Category | B1: Count | D1: SLA Status | E1: Count | G1: Make-Ready | H1: Count | J1: Intent | K1: Count
A2: Plumbing | B2: =COUNTIFS('Work Orders'!D2:D500,A2) | D2: Breached | E2: =COUNTIFS('Work Orders'!L2:L500,D2) | G2: Ready for QC | H2: =COUNTIFS(Turnover!H2:H500,G2) | J2: Renewing | K2: =COUNTIFS(Retention!G2:G500,J2)
A3: Electrical | B3: =COUNTIFS('Work Orders'!D2:D500,A3) | D3: At Risk | E3: =COUNTIFS('Work Orders'!L2:L500,D3) | G3: In Progress | H3: =COUNTIFS(Turnover!H2:H500,G3) | J3: Undecided | K3: =COUNTIFS(Retention!G2:G500,J3)
A4: HVAC | B4: =COUNTIFS('Work Orders'!D2:D500,A4) | D4: On Track | E4: =COUNTIFS('Work Orders'!L2:L500,D4) | G4: Not Started | H4: =COUNTIFS(Turnover!H2:H500,G4) | J4: Unknown | K4: =COUNTIFS(Retention!G2:G500,J4)
A5: Appliance | B5: =COUNTIFS('Work Orders'!D2:D500,A5) | D5: Closed | E5: =COUNTIFS('Work Orders'!L2:L500,D5) | G5: Ready | H5: =COUNTIFS(Turnover!H2:H500,G5) | J5: Not Renewing | K5: =COUNTIFS(Retention!G2:G500,J5)
A6: Lock/Key | B6: =COUNTIFS('Work Orders'!D2:D500,A6)
A7: Pest | B7: =COUNTIFS('Work Orders'!D2:D500,A7)
A8: Common Area | B8: =COUNTIFS('Work Orders'!D2:D500,A8)
A9: Noise | B9: =COUNTIFS('Work Orders'!D2:D500,A9)

Sheet Weekly Report
B1: Weekly Operations Report
B2: ="Week of "&TEXT(TODAY()-6,"mm/dd")&" – "&TEXT(TODAY(),"mm/dd/yyyy")
B4: THIS WEEK'S NUMBERS
B5: Work orders closed this week | C5: =COUNTIFS('Work Orders'!H2:H500,"Closed",'Work Orders'!I2:I500,">="&TODAY()-7)
B6: Average days to close | C6: =IFERROR(ROUND(AVERAGEIFS('Work Orders'!K2:K500,'Work Orders'!H2:H500,"Closed"),1),"—")
B7: SLA breaches right now | C7: =COUNTIFS('Work Orders'!L2:L500,"Breached")
B8: Units made ready this week | C8: =COUNTIFS(Turnover!J2:J500,">="&TODAY()-7)
B9: Renewals secured | C9: =COUNTIFS(Retention!G2:G500,"Renewing")
B10: Avg. service-recovery satisfaction | C10: =IFERROR(ROUND(AVERAGE('Service Recovery'!J2:J500),2),"—")
B12: TOP 3 BREACHES
B13: WO-ID | C13: Unit | D13: Days overdue
A14: =IFERROR(MATCH(1,'Work Orders'!$M$2:$M$500,0)+1,"") | B14: =IF($A14="","",INDEX('Work Orders'!A:A,$A14)) | C14: =IF($A14="","",INDEX('Work Orders'!C:C,$A14)) | D14: =IF($A14="","",INDEX('Work Orders'!K:K,$A14)-INDEX('Work Orders'!J:J,$A14))
A15: =IFERROR(MATCH(2,'Work Orders'!$M$2:$M$500,0)+1,"") | B15: =IF($A15="","",INDEX('Work Orders'!A:A,$A15)) | C15: =IF($A15="","",INDEX('Work Orders'!C:C,$A15)) | D15: =IF($A15="","",INDEX('Work Orders'!K:K,$A15)-INDEX('Work Orders'!J:J,$A15))
A16: =IFERROR(MATCH(3,'Work Orders'!$M$2:$M$500,0)+1,"") | B16: =IF($A16="","",INDEX('Work Orders'!A:A,$A16)) | C16: =IF($A16="","",INDEX('Work Orders'!C:C,$A16)) | D16: =IF($A16="","",INDEX('Work Orders'!K:K,$A16)-INDEX('Work Orders'!J:J,$A16))
B18: How to use this page: print it (or save as PDF) for standup or your 1:1. Every number is live — no manual rollup. Full detail lives in the Action Center.
